Workbook

Sheet logistics_dataset
A1: item_id | B1: category | C1: stock_level | D1: reorder_point | E1: reorder_frequency_days | F1: lead_time_days | G1: daily_demand | H1: demand_std_dev | I1: item_popularity_score | J1: storage_location_id | K1: zone | L1: picking_time_seconds | M1: handling_cost_per_unit | N1: unit_price | O1: holding_cost_per_unit_day | P1: stockout_count_last_month | Q1: order_fulfillment_rate | R1: total_orders_last_month | S1: turnover_ratio | T1: layout_efficiency_score | U1: last_restock_date | V1: forecasted_demand_next_7d | W1: KPI_score | X1: Stock Status | Y1: Demand During Lead Time | Z1: Stockout Risk | AA1: Days of Inventory Left | AB1: Inventory Value | AC1: Monthly Holding Cost | AD1: Fulfillment Performance | AE1: Picking Speed Status
A2: ITM10000 | B2: Pharma | C2: 283 | D2: 21 | E2: 4 | F2: 4 | G2: 49.85 | H2: 1.56 | I2: 0.43 | J2: L82 | K2: B | L2: 106 | M2: 3.61 | N2: 117.8 | O2: 1.14 | P2: 0 | Q2: 0.8 | R2: 700 | S2: 3.33 | T2: 0.33 | U2: 45339 | V2: 184.37 | W2: 0.556 | X2: =IF(WarehouseData[[#This Row],[stock_level]]<=WarehouseData[[#This Row],[reorder_point]],"Low Stock","Sufficient Stock") -> Sufficient Stock | Y2: =WarehouseData[[#This Row],[daily_demand]]*WarehouseData[[#This Row],[lead_time_days]] -> 199.4 | Z2: =IF(WarehouseData[[#This Row],[stock_level]]<=WarehouseData[[#This Row],[Demand During Lead Time]],"At Risk","Safe") -> Safe | AA2: =WarehouseData[[#This Row],[stock_level]]/WarehouseData[[#This Row],[daily_demand]] -> 5.6770311 | AB2: =WarehouseData[[#This Row],[stock_level]]*WarehouseData[[#This Row],[unit_price]] -> 33337.4 | AC2: =WarehouseData[[#This Row],[stock_level]]*WarehouseData[[#This Row],[holding_cost_per_unit_day]]*30 -> 9678.6 | AD2: =IF(WarehouseData[[#This Row],[order_fulfillment_rate]]>=0.9,"Strong",IF(WarehouseData[[#This Row],[order_fulfillment_rate]]>=0.8,"Moderate","Needs Attention")) -> Moderate | AE2: =IF(WarehouseData[[#This Row],[picking_time_seconds]]>120,"Slow",IF(WarehouseData[[#This Row],[picking_time_seconds]]>=60,"Average","Fast")) -> Average
A3: ITM10001 | B3: Automotive | C3: 301 | D3: 52 | E3: 9 | F3: 6 | G3: 23.34 | H3: 2.55 | I3: 0.69 | J3: L15 | K3: A | L3: 45 | M3: 3.54 | N3: 178.8 | O3: 1.09 | P3: 3 | Q3: 0.79 | R3: 736 | S3: 10.36 | T3: 0.98 | U3: 45566 | V3: 221.94 | W3: 0.723 | X3: =IF(WarehouseData[[#This Row],[stock_level]]<=WarehouseData[[#This Row],[reorder_point]],"Low Stock","Sufficient Stock") -> Sufficient Stock | Y3: =WarehouseData[[#This Row],[daily_demand]]*WarehouseData[[#This Row],[lead_time_days]] -> 140.04 | Z3: =IF(WarehouseData[[#This Row],[stock_level]]<=WarehouseData[[#This Row],[Demand During Lead Time]],"At Risk","Safe") -> Safe | AA3: =WarehouseData[[#This Row],[stock_level]]/WarehouseData[[#This Row],[daily_demand]] -> 12.896315 | AB3: =WarehouseData[[#This Row],[stock_level]]*WarehouseData[[#This Row],[unit_price]] -> 53818.8 | AC3: =WarehouseData[[#This Row],[stock_level]]*WarehouseData[[#This Row],[holding_cost_per_unit_day]]*30 -> 9842.7 | AD3: =IF(WarehouseData[[#This Row],[order_fulfillment_rate]]>=0.9,"Strong",IF(WarehouseData[[#This Row],[order_fulfillment_rate]]>=0.8,"Moderate","Needs Attention")) -> Needs Attention | AE3: =IF(WarehouseData[[#This Row],[picking_time_seconds]]>120,"Slow",IF(WarehouseData[[#This Row],[picking_time_seconds]]>=60,"Average","Fast")) -> Fast
A4: ITM10002 | B4: Groceries | C4: 132 | D4: 60 | E4: 11 | F4: 8 | G4: 37.69 | H4: 3.15 | I4: 0.62 | J4: L4 | K4: B | L4: 177 | M4: 0.52 | N4: 54.05 | O4: 0.95 | P4: 7 | Q4: 0.75 | R4: 814 | S4: 14.32 | T4: 0.87 | U4: 45389 | V4: 53.85 | W4: 0.68 | X4: =IF(WarehouseData[[#This Row],[stock_level]]<=WarehouseData[[#This Row],[reorder_point]],"Low Stock","Sufficient Stock") -> Sufficient Stock | Y4: =WarehouseData[[#This Row],[daily_demand]]*WarehouseData[[#This Row],[lead_time_days]] -> 301.52 | Z4: =IF(WarehouseData[[#This Row],[stock_level]]<=WarehouseData[[#This Row],[Demand During Lead Time]],"At Risk","Safe") -> At Risk | AA4: =WarehouseData[[#This Row],[stock_level]]/WarehouseData[[#This Row],[daily_demand]] -> 3.5022552 | AB4: =WarehouseData[[#This Row],[stock_level]]*WarehouseData[[#This Row],[unit_price]] -> 7134.6 | AC4: =WarehouseData[[#This Row],[stock_level]]*WarehouseData[[#This Row],[holding_cost_per_unit_day]]*30 -> 3762 | AD4: =IF(WarehouseData[[#This Row],[order_fulfillment_rate]]>=0.9,"Strong",IF(WarehouseData[[#This Row],[order_fulfillment_rate]]>=0.8,"Moderate","Needs Attention")) -> Needs Attention | AE4: =IF(WarehouseData[[#This Row],[picking_time_seconds]]>120,"Slow",IF(WarehouseData[[#This Row],[picking_time_seconds]]>=60,"Average","Fast")) -> Slow
A5: ITM10003 | B5: Automotive | C5: 346 | D5: 46 | E5: 13 | F5: 5 | G5: 33.69 | H5: 2.79 | I5: 0.21 | J5: L95 | K5: A | L5: 39 | M5: 2.64 | N5: 31.1 | O5: 1.9 | P5: 0 | Q5: 0.96 | R5: 994 | S5: 2.08 | T5: 0.29 | U5: 45318 | V5: 92.04 | W5: 0.488 | X5: =IF(WarehouseData[[#This Row],[stock_level]]<=WarehouseData[[#This Row],[reorder_point]],"Low Stock","Sufficient Stock") -> Sufficient Stock | Y5: =WarehouseData[[#This Row],[daily_demand]]*WarehouseData[[#This Row],[lead_time_days]] -> 168.45 | Z5: =IF(WarehouseData[[#This Row],[stock_level]]<=WarehouseData[[#This Row],[Demand During Lead Time]],"At Risk","Safe") -> Safe | AA5: =WarehouseData[[#This Row],[stock_level]]/WarehouseData[[#This Row],[daily_demand]] -> 10.27011 | AB5: =WarehouseData[[#This Row],[stock_level]]*WarehouseData[[#This Row],[unit_price]] -> 10760.6 | AC5: =WarehouseData[[#This Row],[stock_level]]*WarehouseData[[#This Row],[holding_cost_per_unit_day]]*30 -> 19722 | AD5: =IF(WarehouseData[[#This Row],[order_fulfillment_rate]]>=0.9,"Strong",IF(WarehouseData[[#This Row],[order_fulfillment_rate]]>=0.8,"Moderate","Needs Attention")) -> Strong | AE5: =IF(WarehouseData[[#This Row],[picking_time_seconds]]>120,"Slow",IF(WarehouseData[[#This Row],[picking_time_seconds]]>=60,"Average","Fast")) -> Fast
A6: ITM10004 | B6: Automotive | C6: 49 | D6: 55 | E6: 4 | F6: 6 | G6: 49.58 | H6: 5.23 | I6: 0.31 | J6: L36 | K6: D | L6: 35 | M6: 1.4 | N6: 104.97 | O6: 0.63 | P6: 5 | Q6: 0.83 | R6: 299 | S6: 5.65 | T6: 0.96 | U6: 45429 | V6: 194.58 | W6: 0.67 | X6: =IF(WarehouseData[[#This Row],[stock_level]]<=WarehouseData[[#This Row],[reorder_point]],"Low Stock","Sufficient Stock") -> Low Stock | Y6: =WarehouseData[[#This Row],[daily_demand]]*WarehouseData[[#This Row],[lead_time_days]] -> 297.48 | Z6: =IF(WarehouseData[[#This Row],[stock_level]]<=WarehouseData[[#This Row],[Demand During Lead Time]],"At Risk","Safe") -> At Risk | AA6: =WarehouseData[[#This Row],[stock_level]]/WarehouseData[[#This Row],[daily_demand]] -> 0.98830173 | AB6: =WarehouseData[[#This Row],[stock_level]]*WarehouseData[[#This Row],[unit_price]] -> 5143.53 | AC6: =WarehouseData[[#This Row],[stock_level]]*WarehouseData[[#This Row],[holding_cost_per_unit_day]]*30 -> 926.1 | AD6: =IF(WarehouseData[[#This Row],[order_fulfillment_rate]]>=0.9,"Strong",IF(WarehouseData[[#This Row],[order_fulfillment_rate]]>=0.8,"Moderate","Needs Attention")) -> Moderate | AE6: =IF(WarehouseData[[#This Row],[picking_time_seconds]]>120,"Slow",IF(WarehouseData[[#This Row],[picking_time_seconds]]>=60,"Average","Fast")) -> Fast
A7: ITM10005 | B7: Apparel | C7: 154 | D7: 62 | E7: 9 | F7: 6 | G7: 35.95 | H7: 9.47 | I7: 0.41 | J7: L32 | K7: A | L7: 94 | M7: 1.96 | N7: 164.12 | O7: 0.66 | P7: 1 | Q7: 0.99 | R7: 477 | S7: 7.61 | T7: 0.95 | U7: 45485 | V7: 180.65 | W7: 0.803 | X7: =IF(WarehouseData[[#This Row],[stock_level]]<=WarehouseData[[#This Row],[reorder_point]],"Low Stock","Sufficient Stock") -> Sufficient Stock | Y7: =WarehouseData[[#This Row],[daily_demand]]*WarehouseData[[#This Row],[lead_time_days]] -> 215.7 | Z7: =IF(WarehouseData[[#This Row],[stock_level]]<=WarehouseData[[#This Row],[Demand During Lead Time]],"At Risk","Safe") -> At Risk | AA7: =WarehouseData[[#This Row],[stock_level]]/WarehouseData[[#This Row],[daily_demand]] -> 4.2837274 | AB7: =WarehouseData[[#This Row],[stock_level]]*WarehouseData[[#This Row],[unit_price]] -> 25274.48 | AC7: =WarehouseData[[#This Row],[stock_level]]*WarehouseData[[#This Row],[holding_cost_per_unit_day]]*30 -> 3049.2 | AD7: =IF(WarehouseData[[#This Row],[order_fulfillment_rate]]>=0.9,"Strong",IF(WarehouseData[[#This Row],[order_fulfillment_rate]]>=0.8,"Moderate","Needs Attention")) -> Strong | AE7: =IF(WarehouseData[[#This Row],[picking_time_seconds]]>120,"Slow",IF(WarehouseData[[#This Row],[picking_time_seconds]]>=60,"Average","Fast")) -> Average
A8: ITM10006 | B8: Groceries | C8: 86 | D8: 97 | E8: 6 | F8: 4 | G8: 9.04 | H8: 4.72 | I8: 0.28 | J8: L29 | K8: C | L8: 110 | M8: 4.9 | N8: 134.38 | O8: 0.37 | P8: 8 | Q8: 0.88 | R8: 418 | S8: 4.25 | T8: 0.45 | U8: 45636 | V8: 223.69 | W8: 0.526 | X8: =IF(WarehouseData[[#This Row],[stock_level]]<=WarehouseData[[#This Row],[reorder_point]],"Low Stock","Sufficient Stock") -> Low Stock | Y8: =WarehouseData[[#This Row],[daily_demand]]*WarehouseData[[#This Row],[lead_time_days]] -> 36.16 | Z8: =IF(WarehouseData[[#This Row],[stock_level]]<=WarehouseData[[#This Row],[Demand During Lead Time]],"At Risk","Safe") -> Safe | AA8: =WarehouseData[[#This Row],[stock_level]]/WarehouseData[[#This Row],[daily_demand]] -> 9.5132743 | AB8: =WarehouseData[[#This Row],[stock_level]]*WarehouseData[[#This Row],[unit_price]] -> 11556.68 | AC8: =WarehouseData[[#This Row],[stock_level]]*WarehouseData[[#This Row],[holding_cost_per_unit_day]]*30 -> 954.6 | AD8: =IF(WarehouseData[[#This Row],[order_fulfillment_rate]]>=0.9,"Strong",IF(WarehouseData[[#This Row],[order_fulfillment_rate]]>=0.8,"Moderate","Needs Attention")) -> Moderate | AE8: =IF(WarehouseData[[#This Row],[picking_time_seconds]]>120,"Slow",IF(WarehouseData[[#This Row],[picking_time_seconds]]>=60,"Average","Fast")) -> Average
A9: ITM10007 | B9: Groceries | C9: 84 | D9: 89 | E9: 13 | F9: 4 | G9: 47.82 | H9: 6.78 | I9: 0.24 | J9: L18 | K9: D | L9: 130 | M9: 0.88 | N9: 131.09 | O9: 1.42 | P9: 7 | Q9: 0.74 | R9: 958 | S9: 11.37 | T9: 0.7 | U9: 45601 | V9: 195.75 | W9: 0.558 | X9: =IF(WarehouseData[[#This Row],[stock_level]]<=WarehouseData[[#This Row],[reorder_point]],"Low Stock","Sufficient Stock") -> Low Stock | Y9: =WarehouseData[[#This Row],[daily_demand]]*WarehouseData[[#This Row],[lead_time_days]] -> 191.28 | Z9: =IF(WarehouseData[[#This Row],[stock_level]]<=WarehouseData[[#This Row],[Demand During Lead Time]],"At Risk","Safe") -> At Risk | AA9: =WarehouseData[[#This Row],[stock_level]]/WarehouseData[[#This Row],[daily_demand]] -> 1.7565872 | AB9: =WarehouseData[[#This Row],[stock_level]]*WarehouseData[[#This Row],[unit_price]] -> 11011.56 | AC9: =WarehouseData[[#This Row],[stock_level]]*WarehouseData[[#This Row],[holding_cost_per_unit_day]]*30 -> 3578.4 | AD9: =IF(WarehouseData[[#This Row],[order_fulfillment_rate]]>=0.9,"Strong",IF(WarehouseData[[#This Row],[order_fulfillment_rate]]>=0.8,"Moderate","Needs Attention")) -> Needs Attention | AE9: =IF(WarehouseData[[#This Row],[picking_time_seconds]]>120,"Slow",IF(WarehouseData[[#This Row],[picking_time_seconds]]>=60,"Average","Fast")) -> Slow
A10: ITM10008 | B10: Groceries | C10: 311 | D10: 22 | E10: 4 | F10: 9 | G10: 33.72 | H10: 7.04 | I10: 0.15 | J10: L95 | K10: D | L10: 40 | M10: 3.75 | N10: 13.32 | O10: 0.71 | P10: 8 | Q10: 0.86 | R10: 697 | S10: 10.64 | T10: 0.29 | U10: 45600 | V10: 105.74 | W10: 0.541 | X10: =IF(WarehouseData[[#This Row],[stock_level]]<=WarehouseData[[#This Row],[reorder_point]],"Low Stock","Sufficient Stock") -> Sufficient Stock | Y10: =WarehouseData[[#This Row],[daily_demand]]*WarehouseData[[#This Row],[lead_time_days]] -> 303.48 | Z10: =IF(WarehouseData[[#This Row],[stock_level]]<=WarehouseData[[#This Row],[Demand During Lead Time]],"At Risk","Safe") -> Safe | AA10: =WarehouseData[[#This Row],[stock_level]]/WarehouseData[[#This Row],[daily_demand]] -> 9.223013 | AB10: =WarehouseData[[#This Row],[stock_level]]*WarehouseData[[#This Row],[unit_price]] -> 4142.52 | AC10: =WarehouseData[[#This Row],[stock_level]]*WarehouseData[[#This Row],[holding_cost_per_unit_day]]*30 -> 6624.3 | AD10: =IF(WarehouseData[[#This Row],[order_fulfillment_rate]]>=0.9,"Strong",IF(WarehouseData[[#This Row],[order_fulfillment_rate]]>=0.8,"Moderate","Needs Attention")) -> Moderate | AE10: =IF(WarehouseData[[#This Row],[picking_time_seconds]]>120,"Slow",IF(WarehouseData[[#This Row],[picking_time_seconds]]>=60,"Average","Fast")) -> Fast
A11: ITM10009 | B11: Automotive | C11: 44 | D11: 98 | E11: 9 | F11: 8 | G11: 3.91 | H11: 8.78 | I11: 0.89 | J11: L14 | K11: A | L11: 26 | M11: 1.28 | N11: 70.32 | O11: 1.63 | P11: 8 | Q11: 1 | R11: 496 | S11: 2.65 | T11: 0.27 | U11: 45312 | V11: 154.78 | W11: 0.366 | X11: =IF(WarehouseData[[#This Row],[stock_level]]<=WarehouseData[[#This Row],[reorder_point]],"Low Stock","Sufficient Stock") -> Low Stock | Y11: =WarehouseData[[#This Row],[daily_demand]]*WarehouseData[[#This Row],[lead_time_days]] -> 31.28 | Z11: =IF(WarehouseData[[#This Row],[stock_level]]<=WarehouseData[[#This Row],[Demand During Lead Time]],"At Risk","Safe") -> Safe | AA11: =WarehouseData[[#This Row],[stock_level]]/WarehouseData[[#This Row],[daily_demand]] -> 11.253197 | AB11: =WarehouseData[[#This Row],[stock_level]]*WarehouseData[[#This Row],[unit_price]] -> 3094.08 | AC11: =WarehouseData[[#This Row],[stock_level]]*WarehouseData[[#This Row],[holding_cost_per_unit_day]]*30 -> 2151.6 | AD11: =IF(WarehouseData[[#This Row],[order_fulfillment_rate]]>=0.9,"Strong",IF(WarehouseData[[#This Row],[order_fulfillment_rate]]>=0.8,"Moderate","Needs Attention")) -> Strong | AE11: =IF(WarehouseData[[#This Row],[picking_time_seconds]]>120,"Slow",IF(WarehouseData[[#This Row],[picking_time_seconds]]>=60,"Average","Fast")) -> Fast
A12: ITM10010 | B12: Pharma | C12: 56 | D12: 63 | E12: 7 | F12: 2 | G12: 33.22 | H12: 0.82 | I12: 0.36 | J12: L87 | K12: B | L12: 107 | M12: 0.53 | N12: 188.5 | O12: 1.95 | P12: 1 | Q12: 0.87 | R12: 71 | S12: 8.97 | T12: 0.6 | U12: 45329 | V12: 266.58 | W12: 0.599 | X12: =IF(WarehouseData[[#This Row],[stock_level]]<=WarehouseData[[#This Row],[reorder_point]],"Low Stock","Sufficient Stock") -> Low Stock | Y12: =WarehouseData[[#This Row],[daily_demand]]*WarehouseData[[#This Row],[lead_time_days]] -> 66.44 | Z12: =IF(WarehouseData[[#This Row],[stock_level]]<=WarehouseData[[#This Row],[Demand During Lead Time]],"At Risk","Safe") -> At Risk | AA12: =WarehouseData[[#This Row],[stock_level]]/WarehouseData[[#This Row],[daily_demand]] -> 1.6857315 | AB12: =WarehouseData[[#This Row],[stock_level]]*WarehouseData[[#This Row],[unit_price]] -> 10556 | AC12: =WarehouseData[[#This Row],[stock_level]]*WarehouseData[[#This Row],[holding_cost_per_unit_day]]*30 -> 3276 | AD12: =IF(WarehouseData[[#This Row],[order_fulfillment_rate]]>=0.9,"Strong",IF(WarehouseData[[#This Row],[order_fulfillment_rate]]>=0.8,"Moderate","Needs Attention")) -> Moderate | AE12: =IF(WarehouseData[[#This Row],[picking_time_seconds]]>120,"Slow",IF(WarehouseData[[#This Row],[picking_time_seconds]]>=60,"Average","Fast")) -> Average
A13: ITM10011 | B13: Groceries | C13: 20 | D13: 66 | E13: 3 | F13: 7 | G13: 44.27 | H13: 4.34 | I13: 0.36 | J13: L95 | K13: A | L13: 135 | M13: 2.76 | N13: 35.51 | O13: 0.18 | P13: 1 | Q13: 0.7 | R13: 599 | S13: 6.16 | T13: 0.24 | U13: 45388 | V13: 63.97 | W13: 0.632 | X13: =IF(WarehouseData[[#This Row],[stock_level]]<=WarehouseData[[#This Row],[reorder_point]],"Low Stock","Sufficient Stock") -> Low Stock | Y13: =WarehouseData[[#This Row],[daily_demand]]*WarehouseData[[#This Row],[lead_time_days]] -> 309.89 | Z13: =IF(WarehouseData[[#This Row],[stock_level]]<=WarehouseData[[#This Row],[Demand During Lead Time]],"At Risk","Safe") -> At Risk | AA13: =WarehouseData[[#This Row],[stock_level]]/WarehouseData[[#This Row],[daily_demand]] -> 0.45177321 | AB13: =WarehouseData[[#This Row],[stock_level]]*WarehouseData[[#This Row],[unit_price]] -> 710.2 | AC13: =WarehouseData[[#This Row],[stock_level]]*WarehouseData[[#This Row],[holding_cost_per_unit_day]]*30 -> 108 | AD13: =IF(WarehouseData[[#This Row],[order_fulfillment_rate]]>=0.9,"Strong",IF(WarehouseData[[#This Row],[order_fulfillment_rate]]>=0.8,"Moderate","Needs Attention")) -> Needs Attention | AE13: =IF(WarehouseData[[#This Row],[picking_time_seconds]]>120,"Slow",IF(WarehouseData[[#This Row],[picking_time_seconds]]>=60,"Average","Fast")) -> Slow
... A3205: ITM13203 | B3205: Apparel | C3205: 377 | D3205: 40 | E3205: 14 | F3205: 3 | G3205: 29.4 | H3205: 7.43 | I3205: 0.14 | J3205: L48 | K3205: A | L3205: 56 | M3205: 4.92 | N3205: 39.88 | O3205: 1.94 | P3205: 9 | Q3205: 0.92 | R3205: 812 | S3205: 8.74 | T3205: 0.54 | U3205: 45437 | V3205: 193.91 | W3205: 0.435 | X3205: =IF(WarehouseData[[#This Row],[stock_level]]<=WarehouseData[[#This Row],[reorder_point]],"Low Stock","Sufficient Stock") -> Sufficient Stock | Y3205: =WarehouseData[[#This Row],[daily_demand]]*WarehouseData[[#This Row],[lead_time_days]] -> 88.2 | Z3205: =IF(WarehouseData[[#This Row],[stock_level]]<=WarehouseData[[#This Row],[Demand During Lead Time]],"At Risk","Safe") -> Safe | AA3205: =WarehouseData[[#This Row],[stock_level]]/WarehouseData[[#This Row],[daily_demand]] -> 12.823129 | AB3205: =WarehouseData[[#This Row],[stock_level]]*WarehouseData[[#This Row],[unit_price]] -> 15034.76 | AC3205: =WarehouseData[[#This Row],[stock_level]]*WarehouseData[[#This Row],[holding_cost_per_unit_day]]*30 -> 21941.4 | AD3205: =IF(WarehouseData[[#This Row],[order_fulfillment_rate]]>=0.9,"Strong",IF(WarehouseData[[#This Row],[order_fulfillment_rate]]>=0.8,"Moderate","Needs Attention")) -> Strong | AE3205: =IF(WarehouseData[[#This Row],[picking_time_seconds]]>120,"Slow",IF(WarehouseData[[#This Row],[picking_time_seconds]]>=60,"Average","Fast")) -> Fast

Sheet Pivot_Tables
A1: Pivot Table Summaries - Logistics Database
A4: Pivot 1: Category-wise Inventory Summary | H4: Pivot 2: Stockout Risk by Category
A5: Category | B5: Number of Items | C5: Total Stock | D5: Total Inventory Value | E5: Monthly Holding Cost | F5: Avg Fulfillment Rate | H5: Category | I5: At Risk | J5: Safe | K5: Total Items
A6: Apparel | B6: =COUNTIF(logistics_dataset!$B$2:$B$3205,A6) -> 617 | C6: =SUMIF(logistics_dataset!$B$2:$B$3205,A6,logistics_dataset!$C$2:$C$3205) -> 160416 | D6: =SUMIF(logistics_dataset!$B$2:$B$3205,A6,logistics_dataset!$AB$2:$AB$3205) -> 16804476 | E6: =SUMIF(logistics_dataset!$B$2:$B$3205,A6,logistics_dataset!$AC$2:$AC$3205) -> 4916496.9 | F6: =AVERAGEIF(logistics_dataset!$B$2:$B$3205,A6,logistics_dataset!$Q$2:$Q$3205) -> 0.84742301 | H6: Apparel | I6: =COUNTIFS(logistics_dataset!$B$2:$B$3205,$H6,logistics_dataset!$Z$2:$Z$3205,I$5) -> 156 | J6: =COUNTIFS(logistics_dataset!$B$2:$B$3205,$H6,logistics_dataset!$Z$2:$Z$3205,J$5) -> 461 | K6: =SUM(I6:J6) -> 617
A7: Automotive | B7: =COUNTIF(logistics_dataset!$B$2:$B$3205,A7) -> 658 | C7: =SUMIF(logistics_dataset!$B$2:$B$3205,A7,logistics_dataset!$C$2:$C$3205) -> 170217 | D7: =SUMIF(logistics_dataset!$B$2:$B$3205,A7,logistics_dataset!$AB$2:$AB$3205) -> 18042426 | E7: =SUMIF(logistics_dataset!$B$2:$B$3205,A7,logistics_dataset!$AC$2:$AC$3205) -> 5286221.1 | F7: =AVERAGEIF(logistics_dataset!$B$2:$B$3205,A7,logistics_dataset!$Q$2:$Q$3205) -> 0.8518541 | H7: Automotive | I7: =COUNTIFS(logistics_dataset!$B$2:$B$3205,$H7,logistics_dataset!$Z$2:$Z$3205,I$5) -> 175 | J7: =COUNTIFS(logistics_dataset!$B$2:$B$3205,$H7,logistics_dataset!$Z$2:$Z$3205,J$5) -> 483 | K7: =SUM(I7:J7) -> 658
A8: Electronics | B8: =COUNTIF(logistics_dataset!$B$2:$B$3205,A8) -> 651 | C8: =SUMIF(logistics_dataset!$B$2:$B$3205,A8,logistics_dataset!$C$2:$C$3205) -> 172266 | D8: =SUMIF(logistics_dataset!$B$2:$B$3205,A8,logistics_dataset!$AB$2:$AB$3205) -> 18234366 | E8: =SUMIF(logistics_dataset!$B$2:$B$3205,A8,logistics_dataset!$AC$2:$AC$3205) -> 5396802.3 | F8: =AVERAGEIF(logistics_dataset!$B$2:$B$3205,A8,logistics_dataset!$Q$2:$Q$3205) -> 0.85132104 | H8: Electronics | I8: =COUNTIFS(logistics_dataset!$B$2:$B$3205,$H8,logistics_dataset!$Z$2:$Z$3205,I$5) -> 164 | J8: =COUNTIFS(logistics_dataset!$B$2:$B$3205,$H8,logistics_dataset!$Z$2:$Z$3205,J$5) -> 487 | K8: =SUM(I8:J8) -> 651
A9: Groceries | B9: =COUNTIF(logistics_dataset!$B$2:$B$3205,A9) -> 618 | C9: =SUMIF(logistics_dataset!$B$2:$B$3205,A9,logistics_dataset!$C$2:$C$3205) -> 162997 | D9: =SUMIF(logistics_dataset!$B$2:$B$3205,A9,logistics_dataset!$AB$2:$AB$3205) -> 17342652 | E9: =SUMIF(logistics_dataset!$B$2:$B$3205,A9,logistics_dataset!$AC$2:$AC$3205) -> 5334802.8 | F9: =AVERAGEIF(logistics_dataset!$B$2:$B$3205,A9,logistics_dataset!$Q$2:$Q$3205) -> 0.84768608 | H9: Groceries | I9: =COUNTIFS(logistics_dataset!$B$2:$B$3205,$H9,logistics_dataset!$Z$2:$Z$3205,I$5) -> 168 | J9: =COUNTIFS(logistics_dataset!$B$2:$B$3205,$H9,logistics_dataset!$Z$2:$Z$3205,J$5) -> 450 | K9: =SUM(I9:J9) -> 618
A10: Pharma | B10: =COUNTIF(logistics_dataset!$B$2:$B$3205,A10) -> 660 | C10: =SUMIF(logistics_dataset!$B$2:$B$3205,A10,logistics_dataset!$C$2:$C$3205) -> 178331 | D10: =SUMIF(logistics_dataset!$B$2:$B$3205,A10,logistics_dataset!$AB$2:$AB$3205) -> 19142269 | E10: =SUMIF(logistics_dataset!$B$2:$B$3205,A10,logistics_dataset!$AC$2:$AC$3205) -> 5512060.2 | F10: =AVERAGEIF(logistics_dataset!$B$2:$B$3205,A10,logistics_dataset!$Q$2:$Q$3205) -> 0.85015152 | H10: Pharma | I10: =COUNTIFS(logistics_dataset!$B$2:$B$3205,$H10,logistics_dataset!$Z$2:$Z$3205,I$5) -> 155 | J10: =COUNTIFS(logistics_dataset!$B$2:$B$3205,$H10,logistics_dataset!$Z$2:$Z$3205,J$5) -> 505 | K10: =SUM(I10:J10) -> 660
A13: Pivot 3: Stock Status by Category | H13: Pivot 4: Warehouse Zone Performance
A14: Category | B14: Low Stock | C14: Sufficient Stock | D14: Total Items | H14: Zone | I14: Item Count | J14: Avg Picking Time | K14: Avg Layout Efficiency | L14: Avg KPI Score | M14: Avg Fulfillment Rate
A15: Apparel | B15: =COUNTIFS(logistics_dataset!$B$2:$B$3205,$A15,logistics_dataset!$X$2:$X$3205,B$14) -> 47 | C15: =COUNTIFS(logistics_dataset!$B$2:$B$3205,$A15,logistics_dataset!$X$2:$X$3205,C$14) -> 570 | D15: =SUM(B15:C15) -> 617 | H15: A | I15: =COUNTIF(logistics_dataset!$K$2:$K$3205,H15) -> 812 | J15: =AVERAGEIF(logistics_dataset!$K$2:$K$3205,H15,logistics_dataset!$L$2:$L$3205) -> 93.814039 | K15: =AVERAGEIF(logistics_dataset!$K$2:$K$3205,H15,logistics_dataset!$T$2:$T$3205) -> 0.60248768 | L15: =AVERAGEIF(logistics_dataset!$K$2:$K$3205,H15,logistics_dataset!$W$2:$W$3205) -> 0.605633 | M15: =AVERAGEIF(logistics_dataset!$K$2:$K$3205,H15,logistics_dataset!$Q$2:$Q$3205) -> 0.84899015
A16: Automotive | B16: =COUNTIFS(logistics_dataset!$B$2:$B$3205,$A16,logistics_dataset!$X$2:$X$3205,B$14) -> 54 | C16: =COUNTIFS(logistics_dataset!$B$2:$B$3205,$A16,logistics_dataset!$X$2:$X$3205,C$14) -> 604 | D16: =SUM(B16:C16) -> 658 | H16: B | I16: =COUNTIF(logistics_dataset!$K$2:$K$3205,H16) -> 784 | J16: =AVERAGEIF(logistics_dataset!$K$2:$K$3205,H16,logistics_dataset!$L$2:$L$3205) -> 95.859694 | K16: =AVERAGEIF(logistics_dataset!$K$2:$K$3205,H16,logistics_dataset!$T$2:$T$3205) -> 0.60822704 | L16: =AVERAGEIF(logistics_dataset!$K$2:$K$3205,H16,logistics_dataset!$W$2:$W$3205) -> 0.5976875 | M16: =AVERAGEIF(logistics_dataset!$K$2:$K$3205,H16,logistics_dataset!$Q$2:$Q$3205) -> 0.84454082
A17: Electronics | B17: =COUNTIFS(logistics_dataset!$B$2:$B$3205,$A17,logistics_dataset!$X$2:$X$3205,B$14) -> 46 | C17: =COUNTIFS(logistics_dataset!$B$2:$B$3205,$A17,logistics_dataset!$X$2:$X$3205,C$14) -> 605 | D17: =SUM(B17:C17) -> 651 | H17: C | I17: =COUNTIF(logistics_dataset!$K$2:$K$3205,H17) -> 775 | J17: =AVERAGEIF(logistics_dataset!$K$2:$K$3205,H17,logistics_dataset!$L$2:$L$3205) -> 96.732903 | K17: =AVERAGEIF(logistics_dataset!$K$2:$K$3205,H17,logistics_dataset!$T$2:$T$3205) -> 0.59579355 | L17: =AVERAGEIF(logistics_dataset!$K$2:$K$3205,H17,logistics_dataset!$W$2:$W$3205) -> 0.59941548 | M17: =AVERAGEIF(logistics_dataset!$K$2:$K$3205,H17,logistics_dataset!$Q$2:$Q$3205) -> 0.85227097
A18: Groceries | B18: =COUNTIFS(logistics_dataset!$B$2:$B$3205,$A18,logistics_dataset!$X$2:$X$3205,B$14) -> 47 | C18: =COUNTIFS(logistics_dataset!$B$2:$B$3205,$A18,logistics_dataset!$X$2:$X$3205,C$14) -> 571 | D18: =SUM(B18:C18) -> 618 | H18: D | I18: =COUNTIF(logistics_dataset!$K$2:$K$3205,H18) -> 833 | J18: =AVERAGEIF(logistics_dataset!$K$2:$K$3205,H18,logistics_dataset!$L$2:$L$3205) -> 96.067227 | K18: =AVERAGEIF(logistics_dataset!$K$2:$K$3205,H18,logistics_dataset!$T$2:$T$3205) -> 0.59597839 | L18: =AVERAGEIF(logistics_dataset!$K$2:$K$3205,H18,logistics_dataset!$W$2:$W$3205) -> 0.60390876 | M18: =AVERAGEIF(logistics_dataset!$K$2:$K$3205,H18,logistics_dataset!$Q$2:$Q$3205) -> 0.8530012
A19: Pharma | B19: =COUNTIFS(logistics_dataset!$B$2:$B$3205,$A19,logistics_dataset!$X$2:$X$3205,B$14) -> 46 | C19: =COUNTIFS(logistics_dataset!$B$2:$B$3205,$A19,logistics_dataset!$X$2:$X$3205,C$14) -> 614 | D19: =SUM(B19:C19) -> 660
A22: Pivot 5: Reorder Priority - Top 30 At-Risk Low-Stock Items | J22: Pivot 6: Fulfillment Performance by Category
A23: Rank | B23: Item ID | C23: Category | D23: Zone | E23: Stock Level | F23: Reorder Point | G23: Days Inventory Left | H23: Suggested Action | J23: Category | K23: Strong | L23: Moderate | M23: Needs Attention
A24: =Reorder_Priority!A2 -> 1 | B24: =Reorder_Priority!B2 -> ITM12375 | C24: =Reorder_Priority!C2 -> Automotive | D24: =Reorder_Priority!D2 -> C | E24: =Reorder_Priority!F2 -> 21 | F24: =Reorder_Priority!G2 -> 21 | G24: =Reorder_Priority!J2 -> 0.49528302 | H24: =Reorder_Priority!R2 -> Immediate reorder | J24: Apparel | K24: =COUNTIFS(logistics_dataset!$B$2:$B$3205,$J24,logistics_dataset!$AD$2:$AD$3205,K$23) -> 193 | L24: =COUNTIFS(logistics_dataset!$B$2:$B$3205,$J24,logistics_dataset!$AD$2:$AD$3205,L$23) -> 224 | M24: =COUNTIFS(logistics_dataset!$B$2:$B$3205,$J24,logistics_dataset!$AD$2:$AD$3205,M$23) -> 200
A25: =Reorder_Priority!A3 -> 2 | B25: =Reorder_Priority!B3 -> ITM13191 | C25: =Reorder_Priority!C3 -> Groceries | D25: =Reorder_Priority!D3 -> A | E25: =Reorder_Priority!F3 -> 71 | F25: =Reorder_Priority!G3 -> 77 | G25: =Reorder_Priority!J3 -> 1.4205682 | H25: =Reorder_Priority!R3 -> Immediate reorder | J25: Automotive | K25: =COUNTIFS(logistics_dataset!$B$2:$B$3205,$J25,logistics_dataset!$AD$2:$AD$3205,K$23) -> 236 | L25: =COUNTIFS(logistics_dataset!$B$2:$B$3205,$J25,logistics_dataset!$AD$2:$AD$3205,L$23) -> 218 | M25: =COUNTIFS(logistics_dataset!$B$2:$B$3205,$J25,logistics_dataset!$AD$2:$AD$3205,M$23) -> 204
A26: =Reorder_Priority!A4 -> 3 | B26: =Reorder_Priority!B4 -> ITM10756 | C26: =Reorder_Priority!C4 -> Automotive | D26: =Reorder_Priority!D4 -> C | E26: =Reorder_Priority!F4 -> 41 | F26: =Reorder_Priority!G4 -> 47 | G26: =Reorder_Priority!J4 -> 1.2856695 | H26: =Reorder_Priority!R4 -> Immediate reorder | J26: Electronics | K26: =COUNTIFS(logistics_dataset!$B$2:$B$3205,$J26,logistics_dataset!$AD$2:$AD$3205,K$23) -> 230 | L26: =COUNTIFS(logistics_dataset!$B$2:$B$3205,$J26,logistics_dataset!$AD$2:$AD$3205,L$23) -> 218 | M26: =COUNTIFS(logistics_dataset!$B$2:$B$3205,$J26,logistics_dataset!$AD$2:$AD$3205,M$23) -> 203
A27: =Reorder_Priority!A5 -> 4 | B27: =Reorder_Priority!B5 -> ITM13095 | C27: =Reorder_Priority!C5 -> Groceries | D27: =Reorder_Priority!D5 -> D | E27: =Reorder_Priority!F5 -> 39 | F27: =Reorder_Priority!G5 -> 68 | G27: =Reorder_Priority!J5 -> 0.96320079 | H27: =Reorder_Priority!R5 -> Immediate reorder | J27: Groceries | K27: =COUNTIFS(logistics_dataset!$B$2:$B$3205,$J27,logistics_dataset!$AD$2:$AD$3205,K$23) -> 208 | L27: =COUNTIFS(logistics_dataset!$B$2:$B$3205,$J27,logistics_dataset!$AD$2:$AD$3205,L$23) -> 204 | M27: =COUNTIFS(logistics_dataset!$B$2:$B$3205,$J27,logistics_dataset!$AD$2:$AD$3205,M$23) -> 206
A28: =Reorder_Priority!A6 -> 5 | B28: =Reorder_Priority!B6 -> ITM10245 | C28: =Reorder_Priority!C6 -> Groceries | D28: =Reorder_Priority!D6 -> A | E28: =Reorder_Priority!F6 -> 50 | F28: =Reorder_Priority!G6 -> 78 | G28: =Reorder_Priority!J6 -> 1.1528706 | H28: =Reorder_Priority!R6 -> Immediate reorder | J28: Pharma | K28: =COUNTIFS(logistics_dataset!$B$2:$B$3205,$J28,logistics_dataset!$AD$2:$AD$3205,K$23) -> 236 | L28: =COUNTIFS(logistics_dataset!$B$2:$B$3205,$J28,logistics_dataset!$AD$2:$AD$3205,L$23) -> 213 | M28: =COUNTIFS(logistics_dataset!$B$2:$B$3205,$J28,logistics_dataset!$AD$2:$AD$3205,M$23) -> 211
A29: =Reorder_Priority!A7 -> 6 | B29: =Reorder_Priority!B7 -> ITM11606 | C29: =Reorder_Priority!C7 -> Electronics | D29: =Reorder_Priority!D7 -> B | E29: =Reorder_Priority!F7 -> 41 | F29: =Reorder_Priority!G7 -> 82 | G29: =Reorder_Priority!J7 -> 0.85452272 | H29: =Reorder_Priority!R7 -> Immediate reorder
A30: =Reorder_Priority!A8 -> 7 | B30: =Reorder_Priority!B8 -> ITM12591 | C30: =Reorder_Priority!C8 -> Apparel | D30: =Reorder_Priority!D8 -> B | E30: =Reorder_Priority!F8 -> 25 | F30: =Reorder_Priority!G8 -> 67 | G30: =Reorder_Priority!J8 -> 0.88401697 | H30: =Reorder_Priority!R8 -> Immediate reorder
A31: =Reorder_Priority!A9 -> 8 | B31: =Reorder_Priority!B9 -> ITM10772 | C31: =Reorder_Priority!C9 -> Pharma | D31: =Reorder_Priority!D9 -> C | E31: =Reorder_Priority!F9 -> 28 | F31: =Reorder_Priority!G9 -> 84 | G31: =Reorder_Priority!J9 -> 0.64471563 | H31: =Reorder_Priority!R9 -> Immediate reorder | J31: How to use these tables
A32: =Reorder_Priority!A10 -> 9 | B32: =Reorder_Priority!B10 -> ITM11324 | C32: =Reorder_Priority!C10 -> Apparel | D32: =Reorder_Priority!D10 -> A | E32: =Reorder_Priority!F10 -> 66 | F32: =Reorder_Priority!G10 -> 79 | G32: =Reorder_Priority!J10 -> 1.4775017 | H32: =Reorder_Priority!R10 -> Immediate reorder | J32: 1 | K32: Use Pivot 1 to explain inventory value and category-level stock.
A33: =Reorder_Priority!A11 -> 10 | B33: =Reorder_Priority!B11 -> ITM12039 | C33: =Reorder_Priority!C11 -> Automotive | D33: =Reorder_Priority!D11 -> C | E33: =Reorder_Priority!F11 -> 25 | F33: =Reorder_Priority!G11 -> 96 | G33: =Reorder_Priority!J11 -> 0.55791118 | H33: =Reorder_Priority!R11 -> Immediate reorder | J33: 2 | K33: Use Pivot 2 and Pivot 3 to identify low-stock and stockout-risk categories.
A34: =Reorder_Priority!A12 -> 11 | B34: =Reorder_Priority!B12 -> ITM10505 | C34: =Reorder_Priority!C12 -> Electronics | D34: =Reorder_Priority!D12 -> D | E34: =Reorder_Priority!F12 -> 38 | F34: =Reorder_Priority!G12 -> 68 | G34: =Reorder_Priority!J12 -> 1.1875 | H34: =Reorder_Priority!R12 -> Immediate reorder | J34: 3 | K34: Use Pivot 4 to compare warehouse zone performance and picking speed.
A35: =Reorder_Priority!A13 -> 12 | B35: =Reorder_Priority!B13 -> ITM12728 | C35: =Reorder_Priority!C13 -> Apparel | D35: =Reorder_Priority!D13 -> A | E35: =Reorder_Priority!F13 -> 27 | F35: =Reorder_Priority!G13 -> 48 | G35: =Reorder_Priority!J13 -> 0.54282268 | H35: =Reorder_Priority!R13 -> Immediate reorder | J35: 4 | K35: Use Pivot 5 as the business action table: reorder these items first.
A36: =Reorder_Priority!A14 -> 13 | B36: =Reorder_Priority!B14 -> ITM12990 | C36: =Reorder_Priority!C14 -> Automotive | D36: =Reorder_Priority!D14 -> C | E36: =Reorder_Priority!F14 -> 41 | F36: =Reorder_Priority!G14 -> 73 | G36: =Reorder_Priority!J14 -> 1.2634823 | H36: =Reorder_Priority!R14 -> Immediate reorder | J36: 5 | K36: Use Pivot 6 to explain fulfillment performance by product category.
A37: =Reorder_Priority!A15 -> 14 | B37: =Reorder_Priority!B15 -> ITM12273 | C37: =Reorder_Priority!C15 -> Pharma | D37: =Reorder_Priority!D15 -> D | E37: =Reorder_Priority!F15 -> 29 | F37: =Reorder_Priority!G15 -> 76 | G37: =Reorder_Priority!J15 -> 0.58479532 | H37: =Reorder_Priority!R15 -> Immediate reorder | J37: 6 | K37: For an Excel screenshot, hide gridlines and capture this Pivot_Tables sheet.
A38: =Reorder_Priority!A16 -> 15 | B38: =Reorder_Priority!B16 -> ITM10120 | C38: =Reorder_Priority!C16 -> Apparel | D38: =Reorder_Priority!D16 -> A | E38: =Reorder_Priority!F16 -> 41 | F38: =Reorder_Priority!G16 -> 53 | G38: =Reorder_Priority!J16 -> 0.84553516 | H38: =Reorder_Priority!R16 -> Immediate reorder | J38: 7 | K38: When raw data changes, formulas recalculate automatically.
A39: =Reorder_Priority!A17 -> 16 | B39: =Reorder_Priority!B17 -> ITM11103 | C39: =Reorder_Priority!C17 -> Groceries | D39: =Reorder_Priority!D17 -> D | E39: =Reorder_Priority!F17 -> 58 | F39: =Reorder_Priority!G17 -> 68 | G39: =Reorder_Priority!J17 -> 1.5886059 | H39: =Reorder_Priority!R17 -> Immediate reorder
A40: =Reorder_Priority!A18 -> 17 | B40: =Reorder_Priority!B18 -> ITM12650 | C40: =Reorder_Priority!C18 -> Electronics | D40: =Reorder_Priority!D18 -> B | E40: =Reorder_Priority!F18 -> 44 | F40: =Reorder_Priority!G18 -> 64 | G40: =Reorder_Priority!J18 -> 0.99570038 | H40: =Reorder_Priority!R18 -> Immediate reorder
A41: =Reorder_Priority!A19 -> 18 | B41: =Reorder_Priority!B19 -> ITM12721 | C41: =Reorder_Priority!C19 -> Electronics | D41: =Reorder_Priority!D19 -> D | E41: =Reorder_Priority!F19 -> 36 | F41: =Reorder_Priority!G19 -> 83 | G41: =Reorder_Priority!J19 -> 0.90702948 | H41: =Reorder_Priority!R19 -> Immediate reorder
A42: =Reorder_Priority!A20 -> 19 | B42: =Reorder_Priority!B20 -> ITM10966 | C42: =Reorder_Priority!C20 -> Electronics | D42: =Reorder_Priority!D20 -> A | E42: =Reorder_Priority!F20 -> 25 | F42: =Reorder_Priority!G20 -> 54 | G42: =Reorder_Priority!J20 -> 0.51888751 | H42: =Reorder_Priority!R20 -> Immediate reorder
A43: =Reorder_Priority!A21 -> 20 | B43: =Reorder_Priority!B21 -> ITM13031 | C43: =Reorder_Priority!C21 -> Pharma | D43: =Reorder_Priority!D21 -> D | E43: =Reorder_Priority!F21 -> 34 | F43: =Reorder_Priority!G21 -> 80 | G43: =Reorder_Priority!J21 -> 0.90353441 | H43: =Reorder_Priority!R21 -> Immediate reorder
A44: =Reorder_Priority!A22 -> 21 | B44: =Reorder_Priority!B22 -> ITM10007 | C44: =Reorder_Priority!C22 -> Groceries | D44: =Reorder_Priority!D22 -> D | E44: =Reorder_Priority!F22 -> 84 | F44: =Reorder_Priority!G22 -> 89 | G44: =Reorder_Priority!J22 -> 1.7565872 | H44: =Reorder_Priority!R22 -> Immediate reorder
A45: =Reorder_Priority!A23 -> 22 | B45: =Reorder_Priority!B23 -> ITM12457 | C45: =Reorder_Priority!C23 -> Electronics | D45: =Reorder_Priority!D23 -> C | E45: =Reorder_Priority!F23 -> 25 | F45: =Reorder_Priority!G23 -> 99 | G45: =Reorder_Priority!J23 -> 0.52532045 | H45: =Reorder_Priority!R23 -> Immediate reorder
A46: =Reorder_Priority!A24 -> 23 | B46: =Reorder_Priority!B24 -> ITM11373 | C46: =Reorder_Priority!C24 -> Groceries | D46: =Reorder_Priority!D24 -> D | E46: =Reorder_Priority!F24 -> 26 | F46: =Reorder_Priority!G24 -> 92 | G46: =Reorder_Priority!J24 -> 0.67814293 | H46: =Reorder_Priority!R24 -> Immediate reorder
...

Sheet Category_Analysis
A1: Category | B1: Item Count | C1: Low Stock Items | D1: At Risk Items | E1: Low Stock % | F1: At Risk % | G1: Avg Fulfillment Rate | H1: Avg Picking Time (sec) | I1: Inventory Value | J1: Monthly Holding Cost | K1: Avg KPI Score
A2: Apparel | B2: 617 | C2: 47 | D2: 156 | E2: 0.076175041 | F2: 0.2528363 | G2: 0.84742301 | H2: 97.081037 | I2: 16804476 | J2: 4916496.9 | K2: 0.60337439
A3: Automotive | B3: 658 | C3: 54 | D3: 175 | E3: 0.082066869 | F3: 0.26595745 | G3: 0.8518541 | H3: 95.490881 | I3: 18042426 | J3: 5286221.1 | K3: 0.5997766
A4: Electronics | B4: 651 | C4: 46 | D4: 164 | E4: 0.070660522 | F4: 0.25192012 | G4: 0.85132104 | H4: 96.225806 | I4: 18234366 | J4: 5396802.3 | K4: 0.60164977
A5: Groceries | B5: 618 | C5: 47 | D5: 168 | E5: 0.07605178 | F5: 0.27184466 | G5: 0.84768608 | H5: 94.37055 | I5: 17342652 | J5: 5334802.8 | K5: 0.59627346
A6: Pharma | B6: 660 | C6: 46 | D6: 155 | E6: 0.06969697 | F6: 0.23484848 | G6: 0.85015152 | H6: 94.889394 | I6: 19142269 | J6: 5512060.2 | K6: 0.60736061
A10: Performance Distribution
A11: Metric | B11: Status | C11: Count | D11: Percent of Items
A12: Fulfillment Performance | B12: Strong | C12: 1103 | D12: 0.34425718
A13: Fulfillment Performance | B13: Moderate | C13: 1077 | D13: 0.33614232
A14: Fulfillment Performance | B14: Needs Attention | C14: 1024 | D14: 0.3196005
A15: Picking Speed Status | B15: Fast | C15: 932 | D15: 0.29088639
A16: Picking Speed Status | B16: Average | C16: 1141 | D16: 0.35611735
A17: Picking Speed Status | B17: Slow | C17: 1131 | D17: 0.35299625
A18: Stock Status | B18: Low Stock | C18: 240 | D18: 0.074906367
A19: Stock Status | B19: Sufficient Stock | C19: 2964 | D19: 0.92509363
A20: Stockout Risk | B20: At Risk | C20: 818 | D20: 0.25530587
A21: Stockout Risk | B21: Safe | C21: 2386 | D21: 0.74469413

Sheet Zone_Analysis
A1: Zone | B1: Item Count | C1: Low Stock Items | D1: At Risk Items | E1: Avg Picking Time (sec) | F1: Avg Layout Efficiency | G1: Avg Fulfillment Rate | H1: Inventory Value | I1: Avg KPI Score
A2: A | B2: 812 | C2: 60 | D2: 210 | E2: 93.814039 | F2: 0.60248768 | G2: 0.84899015 | H2: 23101995 | I2: 0.605633
A3: B | B3: 784 | C3: 63 | D3: 193 | E3: 95.859694 | F3: 0.60822704 | G3: 0.84454082 | H3: 21499318 | I3: 0.5976875
A4: C | B4: 775 | C4: 61 | D4: 192 | E4: 96.732903 | F4: 0.59579355 | G4: 0.85227097 | H4: 21237977 | I4: 0.59941548
A5: D | B5: 833 | C5: 56 | D5: 223 | E5: 96.067227 | F5: 0.59597839 | G5: 0.8530012 | H5: 23726899 | I5: 0.60390876

Sheet Reorder_Priority
A1: Rank | B1: Item ID | C1: Category | D1: Zone | E1: Location | F1: Stock Level | G1: Reorder Point | H1: Daily Demand | I1: Demand During Lead Time | J1: Days Inventory Left | K1: Stock Status | L1: Stockout Risk | M1: Stockouts Last Month | N1: Orders Last Month | O1: Forecast Demand 7d | P1: Recommended Reorder Qty | Q1: Priority Score | R1: Suggested Action
A2: 1 | B2: ITM12375 | C2: Automotive | D2: C | E2: L73 | F2: 21 | G2: 21 | H2: 42.4 | I2: 296.8 | J2: 0.49528302 | K2: Low Stock | L2: At Risk | M2: 9 | N2: 802 | O2: 260.14 | P2: 536 | Q2: 127.73 | R2: Immediate reorder
A3: 2 | B3: ITM13191 | C3: Groceries | D3: A | E3: L54 | F3: 71 | G3: 77 | H3: 49.98 | I3: 199.92 | J3: 1.4205682 | K3: Low Stock | L3: At Risk | M3: 9 | N3: 947 | O3: 279.08 | P3: 408 | Q3: 126.15 | R3: Immediate reorder
A4: 3 | B4: ITM10756 | C4: Automotive | D4: C | E4: L69 | F4: 41 | G4: 47 | H4: 31.89 | I4: 287.01 | J4: 1.2856695 | K4: Low Stock | L4: At Risk | M4: 9 | N4: 964 | O4: 217.1 | P4: 464 | Q4: 124.8 | R4: Immediate reorder
A5: 4 | B5: ITM13095 | C5: Groceries | D5: D | E5: L49 | F5: 39 | G5: 68 | H5: 40.49 | I5: 80.98 | J5: 0.96320079 | K5: Low Stock | L5: At Risk | M5: 8 | N5: 805 | O5: 195.15 | P5: 238 | Q5: 124.64 | R5: Immediate reorder
A6: 5 | B6: ITM10245 | C6: Groceries | D6: A | E6: L67 | F6: 50 | G6: 78 | H6: 43.37 | I6: 390.33 | J6: 1.1528706 | K6: Low Stock | L6: At Risk | M6: 9 | N6: 293 | O6: 254.33 | P6: 595 | Q6: 124.49 | R6: Immediate reorder
A7: 6 | B7: ITM11606 | C7: Electronics | D7: B | E7: L17 | F7: 41 | G7: 82 | H7: 47.98 | I7: 239.9 | J7: 0.85452272 | K7: Low Stock | L7: At Risk | M7: 9 | N7: 116 | O7: 272.37 | P7: 472 | Q7: 124.36 | R7: Immediate reorder
A8: 7 | B8: ITM12591 | C8: Apparel | D8: B | E8: L54 | F8: 25 | G8: 67 | H8: 28.28 | I8: 169.68 | J8: 0.88401697 | K8: Low Stock | L8: At Risk | M8: 8 | N8: 908 | O8: 199.28 | P8: 344 | Q8: 124.17 | R8: Immediate reorder
A9: 8 | B9: ITM10772 | C9: Pharma | D9: C | E9: L52 | F9: 28 | G9: 84 | H9: 43.43 | I9: 390.87 | J9: 0.64471563 | K9: Low Stock | L9: At Risk | M9: 9 | N9: 122 | O9: 198.16 | P9: 562 | Q9: 123.74 | R9: Immediate reorder
A10: 9 | B10: ITM11324 | C10: Apparel | D10: A | E10: L87 | F10: 66 | G10: 79 | H10: 44.67 | I10: 402.03 | J10: 1.4775017 | K10: Low Stock | L10: At Risk | M10: 9 | N10: 756 | O10: 183.66 | P10: 520 | Q10: 123.22 | R10: Immediate reorder
A11: 10 | B11: ITM12039 | C11: Automotive | D11: C | E11: L17 | F11: 25 | G11: 96 | H11: 44.81 | I11: 179.24 | J11: 0.55791118 | K11: Low Stock | L11: At Risk | M11: 8 | N11: 122 | O11: 275.89 | P11: 431 | Q11: 123.15 | R11: Immediate reorder
A12: 11 | B12: ITM10505 | C12: Electronics | D12: D | E12: L23 | F12: 38 | G12: 68 | H12: 32 | I12: 160 | J12: 1.1875 | K12: Low Stock | L12: At Risk | M12: 8 | N12: 226 | O12: 295.31 | P12: 418 | Q12: 123.07 | R12: Immediate reorder
A13: 12 | B13: ITM12728 | C13: Apparel | D13: A | E13: L93 | F13: 27 | G13: 48 | H13: 49.74 | I13: 348.18 | J13: 0.54282268 | K13: Low Stock | L13: At Risk | M13: 9 | N13: 418 | O13: 89.8 | P13: 411 | Q13: 122.96 | R13: Immediate reorder
... A31: 30 | B31: ITM10308 | C31: Automotive | D31: D | E31: L18 | F31: 36 | G31: 69 | H31: 44.01 | I31: 308.07 | J31: 0.81799591 | K31: Low Stock | L31: At Risk | M31: 9 | N31: 388 | O31: 59.88 | P31: 332 | Q31: 119.78 | R31: Immediate reorder

Sheet Dashboard_v2
A1: Warehouse Logistics Dashboard - Enhanced Summary
A2: Built from the logistics_dataset table: stock risk, fulfillment, picking speed, inventory value, and holding cost.
A4: Total Items | B4: 3204 | C4: Low Stock Items | D4: 240 | E4: Stockout Risk Items | F4: 818 | G4: Immediate Reorder Items | H4: 279
A5: Avg Fulfillment Rate | B5: 0.84973783 | C5: Avg Picking Time | D5: 95.606429 | E5: Total Inventory Value | F5: 89566189 | G5: Monthly Holding Cost | H5: 26446383
A8: Category | B8: Item Count | C8: Low Stock | D8: At Risk | E8: Inventory Value | G8: Zone | H8: Item Count | I8: Low Stock | J8: At Risk | K8: Avg Picking Time
A9: Apparel | B9: 617 | C9: 47 | D9: 156 | E9: 16804476 | G9: A | H9: 812 | I9: 60 | J9: 210 | K9: 93.814039
A10: Automotive | B10: 658 | C10: 54 | D10: 175 | E10: 18042426 | G10: B | H10: 784 | I10: 63 | J10: 193 | K10: 95.859694
A11: Electronics | B11: 651 | C11: 46 | D11: 164 | E11: 18234366 | G11: C | H11: 775 | I11: 61 | J11: 192 | K11: 96.732903
A12: Groceries | B12: 618 | C12: 47 | D12: 168 | E12: 17342652 | G12: D | H12: 833 | I12: 56 | J12: 223 | K12: 96.067227
A13: Pharma | B13: 660 | C13: 46 | D13: 155 | E13: 19142269
A16: Key Insight | B16: What it means
A17: Stock risk | B17: 818 items are at risk of stockout (25.5% of the dataset).
A18: Low stock | B18: 240 items are below or equal to reorder point.
A19: Picking speed | B19: Average picking time is 95.6 seconds; zone analysis helps identify bottlenecks.
A20: Cost focus | B20: Monthly holding cost is about $26,446,383; compare cost reduction with stockout risk before lowering inventory.
